Workbook

Sheet hu_per_vertebra
A1: token | B1: config | C1: vertebra | D1: mean_HU | E1: sd_HU | F1: voxel_count | G1: classification | H1: age | I1: sex
A2: 36 | B2: fused | C2: L1 | D2: 176 | E2: 138.97 | F2: 19792 | G2: normal | H2: =_xlfn.LET(_xlpm.v, IFERROR(VLOOKUP($A2, manifest!$A:$E, 3, FALSE), ""), IF(OR(_xlpm.v=0, _xlpm.v=""), "", _xlpm.v)) -> 69 | I2: =_xlfn.LET(_xlpm.v, IFERROR(VLOOKUP($A2, manifest!$A:$E, 5, FALSE), ""), IF(OR(_xlpm.v=0, _xlpm.v=""), "", _xlpm.v)) -> female
A3: 36 | B3: fused | C3: L2 | D3: 180.66 | E3: 154.2 | F3: 23409 | H3: =_xlfn.LET(_xlpm.v, IFERROR(VLOOKUP($A3, manifest!$A:$E, 3, FALSE), ""), IF(OR(_xlpm.v=0, _xlpm.v=""), "", _xlpm.v)) -> 69 | I3: =_xlfn.LET(_xlpm.v, IFERROR(VLOOKUP($A3, manifest!$A:$E, 5, FALSE), ""), IF(OR(_xlpm.v=0, _xlpm.v=""), "", _xlpm.v)) -> female
A4: 36 | B4: fused | C4: L3 | D4: 199.29 | E4: 121.2 | F4: 25716 | H4: =_xlfn.LET(_xlpm.v, IFERROR(VLOOKUP($A4, manifest!$A:$E, 3, FALSE), ""), IF(OR(_xlpm.v=0, _xlpm.v=""), "", _xlpm.v)) -> 69 | I4: =_xlfn.LET(_xlpm.v, IFERROR(VLOOKUP($A4, manifest!$A:$E, 5, FALSE), ""), IF(OR(_xlpm.v=0, _xlpm.v=""), "", _xlpm.v)) -> female
A5: 36 | B5: fused | C5: L4 | D5: 281.76 | E5: 200.65 | F5: 35461 | H5: =_xlfn.LET(_xlpm.v, IFERROR(VLOOKUP($A5, manifest!$A:$E, 3, FALSE), ""), IF(OR(_xlpm.v=0, _xlpm.v=""), "", _xlpm.v)) -> 69 | I5: =_xlfn.LET(_xlpm.v, IFERROR(VLOOKUP($A5, manifest!$A:$E, 5, FALSE), ""), IF(OR(_xlpm.v=0, _xlpm.v=""), "", _xlpm.v)) -> female
A6: 36 | B6: fused | C6: L5 | D6: 210.94 | E6: 156.82 | F6: 43094 | H6: =_xlfn.LET(_xlpm.v, IFERROR(VLOOKUP($A6, manifest!$A:$E, 3, FALSE), ""), IF(OR(_xlpm.v=0, _xlpm.v=""), "", _xlpm.v)) -> 69 | I6: =_xlfn.LET(_xlpm.v, IFERROR(VLOOKUP($A6, manifest!$A:$E, 5, FALSE), ""), IF(OR(_xlpm.v=0, _xlpm.v=""), "", _xlpm.v)) -> female
A7: 13 | B7: fused | C7: L1 | D7: 255.84 | E7: 109.77 | F7: 23607 | G7: normal | H7: =_xlfn.LET(_xlpm.v, IFERROR(VLOOKUP($A7, manifest!$A:$E, 3, FALSE), ""), IF(OR(_xlpm.v=0, _xlpm.v=""), "", _xlpm.v)) -> 52 | I7: =_xlfn.LET(_xlpm.v, IFERROR(VLOOKUP($A7, manifest!$A:$E, 5, FALSE), ""), IF(OR(_xlpm.v=0, _xlpm.v=""), "", _xlpm.v)) -> female
A8: 13 | B8: fused | C8: L2 | D8: 292.45 | E8: 179.65 | F8: 22938 | H8: =_xlfn.LET(_xlpm.v, IFERROR(VLOOKUP($A8, manifest!$A:$E, 3, FALSE), ""), IF(OR(_xlpm.v=0, _xlpm.v=""), "", _xlpm.v)) -> 52 | I8: =_xlfn.LET(_xlpm.v, IFERROR(VLOOKUP($A8, manifest!$A:$E, 5, FALSE), ""), IF(OR(_xlpm.v=0, _xlpm.v=""), "", _xlpm.v)) -> female
A9: 13 | B9: fused | C9: L3 | D9: 279.58 | E9: 185.05 | F9: 26413 | H9: =_xlfn.LET(_xlpm.v, IFERROR(VLOOKUP($A9, manifest!$A:$E, 3, FALSE), ""), IF(OR(_xlpm.v=0, _xlpm.v=""), "", _xlpm.v)) -> 52 | I9: =_xlfn.LET(_xlpm.v, IFERROR(VLOOKUP($A9, manifest!$A:$E, 5, FALSE), ""), IF(OR(_xlpm.v=0, _xlpm.v=""), "", _xlpm.v)) -> female
A10: 13 | B10: fused | C10: L4 | D10: 290.56 | E10: 222.85 | F10: 28974 | H10: =_xlfn.LET(_xlpm.v, IFERROR(VLOOKUP($A10, manifest!$A:$E, 3, FALSE), ""), IF(OR(_xlpm.v=0, _xlpm.v=""), "", _xlpm.v)) -> 52 | I10: =_xlfn.LET(_xlpm.v, IFERROR(VLOOKUP($A10, manifest!$A:$E, 5, FALSE), ""), IF(OR(_xlpm.v=0, _xlpm.v=""), "", _xlpm.v)) -> female
A11: 13 | B11: fused | C11: L5 | D11: 281.36 | E11: 180.2 | F11: 36225 | H11: =_xlfn.LET(_xlpm.v, IFERROR(VLOOKUP($A11, manifest!$A:$E, 3, FALSE), ""), IF(OR(_xlpm.v=0, _xlpm.v=""), "", _xlpm.v)) -> 52 | I11: =_xlfn.LET(_xlpm.v, IFERROR(VLOOKUP($A11, manifest!$A:$E, 5, FALSE), ""), IF(OR(_xlpm.v=0, _xlpm.v=""), "", _xlpm.v)) -> female
A12: 26 | B12: spine_only | C12: L1 | D12: 166.4 | E12: 122.52 | F12: 33167 | G12: normal | H12: =_xlfn.LET(_xlpm.v, IFERROR(VLOOKUP($A12, manifest!$A:$E, 3, FALSE), ""), IF(OR(_xlpm.v=0, _xlpm.v=""), "", _xlpm.v)) -> 51 | I12: =_xlfn.LET(_xlpm.v, IFERROR(VLOOKUP($A12, manifest!$A:$E, 5, FALSE), ""), IF(OR(_xlpm.v=0, _xlpm.v=""), "", _xlpm.v)) -> male
A13: 26 | B13: spine_only | C13: L2 | D13: 182.18 | E13: 169.4 | F13: 40649 | H13: =_xlfn.LET(_xlpm.v, IFERROR(VLOOKUP($A13, manifest!$A:$E, 3, FALSE), ""), IF(OR(_xlpm.v=0, _xlpm.v=""), "", _xlpm.v)) -> 51 | I13: =_xlfn.LET(_xlpm.v, IFERROR(VLOOKUP($A13, manifest!$A:$E, 5, FALSE), ""), IF(OR(_xlpm.v=0, _xlpm.v=""), "", _xlpm.v)) -> male
A14: 26 | B14: spine_only | C14: L3 | D14: 159.41 | E14: 129.15 | F14: 42960 | H14: =_xlfn.LET(_xlpm.v, IFERROR(VLOOKUP($A14, manifest!$A:$E, 3, FALSE), ""), IF(OR(_xlpm.v=0, _xlpm.v=""), "", _xlpm.v)) -> 51 | I14: =_xlfn.LET(_xlpm.v, IFERROR(VLOOKUP($A14, manifest!$A:$E, 5, FALSE), ""), IF(OR(_xlpm.v=0, _xlpm.v=""), "", _xlpm.v)) -> male
A15: 26 | B15: spine_only | C15: L4 | D15: 165.89 | E15: 133.76 | F15: 47657 | H15: =_xlfn.LET(_xlpm.v, IFERROR(VLOOKUP($A15, manifest!$A:$E, 3, FALSE), ""), IF(OR(_xlpm.v=0, _xlpm.v=""), "", _xlpm.v)) -> 51 | I15: =_xlfn.LET(_xlpm.v, IFERROR(VLOOKUP($A15, manifest!$A:$E, 5, FALSE), ""), IF(OR(_xlpm.v=0, _xlpm.v=""), "", _xlpm.v)) -> male
A16: 26 | B16: spine_only | C16: L5 | D16: 181.18 | E16: 139.37 | F16: 50902 | H16: =_xlfn.LET(_xlpm.v, IFERROR(VLOOKUP($A16, manifest!$A:$E, 3, FALSE), ""), IF(OR(_xlpm.v=0, _xlpm.v=""), "", _xlpm.v)) -> 51 | I16: =_xlfn.LET(_xlpm.v, IFERROR(VLOOKUP($A16, manifest!$A:$E, 5, FALSE), ""), IF(OR(_xlpm.v=0, _xlpm.v=""), "", _xlpm.v)) -> male
A17: 4 | B17: spine_only | C17: L1 | D17: 123.53 | E17: 80.98 | F17: 32412 | G17: osteopenia | H17: =_xlfn.LET(_xlpm.v, IFERROR(VLOOKUP($A17, manifest!$A:$E, 3, FALSE), ""), IF(OR(_xlpm.v=0, _xlpm.v=""), "", _xlpm.v)) -> 51 | I17: =_xlfn.LET(_xlpm.v, IFERROR(VLOOKUP($A17, manifest!$A:$E, 5, FALSE), ""), IF(OR(_xlpm.v=0, _xlpm.v=""), "", _xlpm.v)) -> male
A18: 4 | B18: spine_only | C18: L2 | D18: 134.12 | E18: 106.5 | F18: 29262 | H18: =_xlfn.LET(_xlpm.v, IFERROR(VLOOKUP($A18, manifest!$A:$E, 3, FALSE), ""), IF(OR(_xlpm.v=0, _xlpm.v=""), "", _xlpm.v)) -> 51 | I18: =_xlfn.LET(_xlpm.v, IFERROR(VLOOKUP($A18, manifest!$A:$E, 5, FALSE), ""), IF(OR(_xlpm.v=0, _xlpm.v=""), "", _xlpm.v)) -> male
A19: 4 | B19: spine_only | C19: L3 | D19: 131.88 | E19: 116.27 | F19: 33216 | H19: =_xlfn.LET(_xlpm.v, IFERROR(VLOOKUP($A19, manifest!$A:$E, 3, FALSE), ""), IF(OR(_xlpm.v=0, _xlpm.v=""), "", _xlpm.v)) -> 51 | I19: =_xlfn.LET(_xlpm.v, IFERROR(VLOOKUP($A19, manifest!$A:$E, 5, FALSE), ""), IF(OR(_xlpm.v=0, _xlpm.v=""), "", _xlpm.v)) -> male
A20: 4 | B20: spine_only | C20: L4 | D20: 129.85 | E20: 110.83 | F20: 38913 | H20: =_xlfn.LET(_xlpm.v, IFERROR(VLOOKUP($A20, manifest!$A:$E, 3, FALSE), ""), IF(OR(_xlpm.v=0, _xlpm.v=""), "", _xlpm.v)) -> 51 | I20: =_xlfn.LET(_xlpm.v, IFERROR(VLOOKUP($A20, manifest!$A:$E, 5, FALSE), ""), IF(OR(_xlpm.v=0, _xlpm.v=""), "", _xlpm.v)) -> male
A21: 4 | B21: spine_only | C21: L5 | D21: 123.25 | E21: 100.83 | F21: 45209 | H21: =_xlfn.LET(_xlpm.v, IFERROR(VLOOKUP($A21, manifest!$A:$E, 3, FALSE), ""), IF(OR(_xlpm.v=0, _xlpm.v=""), "", _xlpm.v)) -> 51 | I21: =_xlfn.LET(_xlpm.v, IFERROR(VLOOKUP($A21, manifest!$A:$E, 5, FALSE), ""), IF(OR(_xlpm.v=0, _xlpm.v=""), "", _xlpm.v)) -> male
A22: 4 | B22: spine_only | C22: L6 | D22: 146.7 | E22: 121.59 | F22: 54479 | H22: =_xlfn.LET(_xlpm.v, IFERROR(VLOOKUP($A22, manifest!$A:$E, 3, FALSE), ""), IF(OR(_xlpm.v=0, _xlpm.v=""), "", _xlpm.v)) -> 51 | I22: =_xlfn.LET(_xlpm.v, IFERROR(VLOOKUP($A22, manifest!$A:$E, 5, FALSE), ""), IF(OR(_xlpm.v=0, _xlpm.v=""), "", _xlpm.v)) -> male
A23: 42 | B23: spine_only | C23: L1 | D23: 211.15 | E23: 144.6 | F23: 44198 | G23: normal | H23: =_xlfn.LET(_xlpm.v, IFERROR(VLOOKUP($A23, manifest!$A:$E, 3, FALSE), ""), IF(OR(_xlpm.v=0, _xlpm.v=""), "", _xlpm.v)) -> 52 | I23: =_xlfn.LET(_xlpm.v, IFERROR(VLOOKUP($A23, manifest!$A:$E, 5, FALSE), ""), IF(OR(_xlpm.v=0, _xlpm.v=""), "", _xlpm.v)) -> female
A24: 42 | B24: spine_only | C24: L2 | D24: 238.39 | E24: 197.33 | F24: 48681 | H24: =_xlfn.LET(_xlpm.v, IFERROR(VLOOKUP($A24, manifest!$A:$E, 3, FALSE), ""), IF(OR(_xlpm.v=0, _xlpm.v=""), "", _xlpm.v)) -> 52 | I24: =_xlfn.LET(_xlpm.v, IFERROR(VLOOKUP($A24, manifest!$A:$E, 5, FALSE), ""), IF(OR(_xlpm.v=0, _xlpm.v=""), "", _xlpm.v)) -> female
A25: 42 | B25: spine_only | C25: L3 | D25: 233.74 | E25: 200.51 | F25: 59253 | H25: =_xlfn.LET(_xlpm.v, IFERROR(VLOOKUP($A25, manifest!$A:$E, 3, FALSE), ""), IF(OR(_xlpm.v=0, _xlpm.v=""), "", _xlpm.v)) -> 52 | I25: =_xlfn.LET(_xlpm.v, IFERROR(VLOOKUP($A25, manifest!$A:$E, 5, FALSE), ""), IF(OR(_xlpm.v=0, _xlpm.v=""), "", _xlpm.v)) -> female
A26: 42 | B26: spine_only | C26: L4 | D26: 203.08 | E26: 150.41 | F26: 61122 | H26: =_xlfn.LET(_xlpm.v, IFERROR(VLOOKUP($A26, manifest!$A:$E, 3, FALSE), ""), IF(OR(_xlpm.v=0, _xlpm.v=""), "", _xlpm.v)) -> 52 | I26: =_xlfn.LET(_xlpm.v, IFERROR(VLOOKUP($A26, manifest!$A:$E, 5, FALSE), ""), IF(OR(_xlpm.v=0, _xlpm.v=""), "", _xlpm.v)) -> female
A27: 42 | B27: spine_only | C27: L5 | D27: 188.12 | E27: 122.48 | F27: 81021 | H27: =_xlfn.LET(_xlpm.v, IFERROR(VLOOKUP($A27, manifest!$A:$E, 3, FALSE), ""), IF(OR(_xlpm.v=0, _xlpm.v=""), "", _xlpm.v)) -> 52 | I27: =_xlfn.LET(_xlpm.v, IFERROR(VLOOKUP($A27, manifest!$A:$E, 5, FALSE), ""), IF(OR(_xlpm.v=0, _xlpm.v=""), "", _xlpm.v)) -> female
A28: 33 | B28: fused | C28: L1 | D28: 260.27 | E28: 213.54 | F28: 26766 | G28: normal | H28: =_xlfn.LET(_xlpm.v, IFERROR(VLOOKUP($A28, manifest!$A:$E, 3, FALSE), ""), IF(OR(_xlpm.v=0, _xlpm.v=""), "", _xlpm.v)) -> 61 | I28: =_xlfn.LET(_xlpm.v, IFERROR(VLOOKUP($A28, manifest!$A:$E, 5, FALSE), ""), IF(OR(_xlpm.v=0, _xlpm.v=""), "", _xlpm.v)) -> female
A29: 33 | B29: fused | C29: L2 | D29: 232.34 | E29: 208.5 | F29: 33431 | H29: =_xlfn.LET(_xlpm.v, IFERROR(VLOOKUP($A29, manifest!$A:$E, 3, FALSE), ""), IF(OR(_xlpm.v=0, _xlpm.v=""), "", _xlpm.v)) -> 61 | I29: =_xlfn.LET(_xlpm.v, IFERROR(VLOOKUP($A29, manifest!$A:$E, 5, FALSE), ""), IF(OR(_xlpm.v=0, _xlpm.v=""), "", _xlpm.v)) -> female
A30: 33 | B30: fused | C30: L3 | D30: 207.76 | E30: 188.4 | F30: 49483 | H30: =_xlfn.LET(_xlpm.v, IFERROR(VLOOKUP($A30, manifest!$A:$E, 3, FALSE), ""), IF(OR(_xlpm.v=0, _xlpm.v=""), "", _xlpm.v)) -> 61 | I30: =_xlfn.LET(_xlpm.v, IFERROR(VLOOKUP($A30, manifest!$A:$E, 5, FALSE), ""), IF(OR(_xlpm.v=0, _xlpm.v=""), "", _xlpm.v)) -> female
A31: 33 | B31: fused | C31: L4 | D31: 246.59 | E31: 245.4 | F31: 55116 | H31: =_xlfn.LET(_xlpm.v, IFERROR(VLOOKUP($A31, manifest!$A:$E, 3, FALSE), ""), IF(OR(_xlpm.v=0, _xlpm.v=""), "", _xlpm.v)) -> 61 | I31: =_xlfn.LET(_xlpm.v, IFERROR(VLOOKUP($A31, manifest!$A:$E, 5, FALSE), ""), IF(OR(_xlpm.v=0, _xlpm.v=""), "", _xlpm.v)) -> female
A32: 33 | B32: fused | C32: L5 | D32: 229.94 | E32: 212.93 | F32: 61280 | H32: =_xlfn.LET(_xlpm.v, IFERROR(VLOOKUP($A32, manifest!$A:$E, 3, FALSE), ""), IF(OR(_xlpm.v=0, _xlpm.v=""), "", _xlpm.v)) -> 61 | I32: =_xlfn.LET(_xlpm.v, IFERROR(VLOOKUP($A32, manifest!$A:$E, 5, FALSE), ""), IF(OR(_xlpm.v=0, _xlpm.v=""), "", _xlpm.v)) -> female
A33: 6 | B33: spine_only | C33: L1 | D33: 199.86 | E33: 194.47 | F33: 37076 | G33: normal | H33: =_xlfn.LET(_xlpm.v, IFERROR(VLOOKUP($A33, manifest!$A:$E, 3, FALSE), ""), IF(OR(_xlpm.v=0, _xlpm.v=""), "", _xlpm.v)) -> 50 | I33: =_xlfn.LET(_xlpm.v, IFERROR(VLOOKUP($A33, manifest!$A:$E, 5, FALSE), ""), IF(OR(_xlpm.v=0, _xlpm.v=""), "", _xlpm.v)) -> male
A34: 6 | B34: spine_only | C34: L2 | D34: 213.18 | E34: 211.43 | F34: 41718 | H34: =_xlfn.LET(_xlpm.v, IFERROR(VLOOKUP($A34, manifest!$A:$E, 3, FALSE), ""), IF(OR(_xlpm.v=0, _xlpm.v=""), "", _xlpm.v)) -> 50 | I34: =_xlfn.LET(_xlpm.v, IFERROR(VLOOKUP($A34, manifest!$A:$E, 5, FALSE), ""), IF(OR(_xlpm.v=0, _xlpm.v=""), "", _xlpm.v)) -> male
A35: 6 | B35: spine_only | C35: L3 | D35: 188.44 | E35: 178.87 | F35: 47744 | H35: =_xlfn.LET(_xlpm.v, IFERROR(VLOOKUP($A35, manifest!$A:$E, 3, FALSE), ""), IF(OR(_xlpm.v=0, _xlpm.v=""), "", _xlpm.v)) -> 50 | I35: =_xlfn.LET(_xlpm.v, IFERROR(VLOOKUP($A35, manifest!$A:$E, 5, FALSE), ""), IF(OR(_xlpm.v=0, _xlpm.v=""), "", _xlpm.v)) -> male
A36: 6 | B36: spine_only | C36: L4 | D36: 196.87 | E36: 191.05 | F36: 51947 | H36: =_xlfn.LET(_xlpm.v, IFERROR(VLOOKUP($A36, manifest!$A:$E, 3, FALSE), ""), IF(OR(_xlpm.v=0, _xlpm.v=""), "", _xlpm.v)) -> 50 | I36: =_xlfn.LET(_xlpm.v, IFERROR(VLOOKUP($A36, manifest!$A:$E, 5, FALSE), ""), IF(OR(_xlpm.v=0, _xlpm.v=""), "", _xlpm.v)) -> male
A37: 6 | B37: spine_only | C37: L5 | D37: 193.29 | E37: 185.46 | F37: 61986 | H37: =_xlfn.LET(_xlpm.v, IFERROR(VLOOKUP($A37, manifest!$A:$E, 3, FALSE), ""), IF(OR(_xlpm.v=0, _xlpm.v=""), "", _xlpm.v)) -> 50 | I37: =_xlfn.LET(_xlpm.v, IFERROR(VLOOKUP($A37, manifest!$A:$E, 5, FALSE), ""), IF(OR(_xlpm.v=0, _xlpm.v=""), "", _xlpm.v)) -> male
A38: 54 | B38: spine_only | C38: L1 | D38: 199.32 | E38: 113.55 | F38: 21802 | G38: normal | H38: =_xlfn.LET(_xlpm.v, IFERROR(VLOOKUP($A38, manifest!$A:$E, 3, FALSE), ""), IF(OR(_xlpm.v=0, _xlpm.v=""), "", _xlpm.v)) | I38: =_xlfn.LET(_xlpm.v, IFERROR(VLOOKUP($A38, manifest!$A:$E, 5, FALSE), ""), IF(OR(_xlpm.v=0, _xlpm.v=""), "", _xlpm.v)) -> male
A39: 54 | B39: spine_only | C39: L2 | D39: 203.6 | E39: 124.65 | F39: 21954 | H39: =_xlfn.LET(_xlpm.v, IFERROR(VLOOKUP($A39, manifest!$A:$E, 3, FALSE), ""), IF(OR(_xlpm.v=0, _xlpm.v=""), "", _xlpm.v)) | I39: =_xlfn.LET(_xlpm.v, IFERROR(VLOOKUP($A39, manifest!$A:$E, 5, FALSE), ""), IF(OR(_xlpm.v=0, _xlpm.v=""), "", _xlpm.v)) -> male
A40: 54 | B40: spine_only | C40: L3 | D40: 205.05 | E40: 125.2 | F40: 25335 | H40: =_xlfn.LET(_xlpm.v, IFERROR(VLOOKUP($A40, manifest!$A:$E, 3, FALSE), ""), IF(OR(_xlpm.v=0, _xlpm.v=""), "", _xlpm.v)) | I40: =_xlfn.LET(_xlpm.v, IFERROR(VLOOKUP($A40, manifest!$A:$E, 5, FALSE), ""), IF(OR(_xlpm.v=0, _xlpm.v=""), "", _xlpm.v)) -> male
...

Sheet demographics
A1: token | B1: config | C1: vertebra | D1: mean_HU | E1: sd_HU | F1: voxel_count | G1: classification | H1: age | I1: sex
A2: 36 | B2: fused | C2: L1 | D2: 176 | E2: 138.97 | F2: 19792 | G2: normal | H2: 69 | I2: female
A3: 13 | B3: fused | C3: L1 | D3: 255.84 | E3: 109.77 | F3: 23607 | G3: normal | H3: 52 | I3: female
A4: 26 | B4: spine_only | C4: L1 | D4: 166.4 | E4: 122.52 | F4: 33167 | G4: normal | H4: 51 | I4: male
A5: 4 | B5: spine_only | C5: L1 | D5: 123.53 | E5: 80.98 | F5: 32412 | G5: osteopenia | H5: 51 | I5: male
A6: 42 | B6: spine_only | C6: L1 | D6: 211.15 | E6: 144.6 | F6: 44198 | G6: normal | H6: 52 | I6: female
A7: 33 | B7: fused | C7: L1 | D7: 260.27 | E7: 213.54 | F7: 26766 | G7: normal | H7: 61 | I7: female
A8: 6 | B8: spine_only | C8: L1 | D8: 199.86 | E8: 194.47 | F8: 37076 | G8: normal | H8: 50 | I8: male
A9: 54 | B9: spine_only | C9: L1 | D9: 199.32 | E9: 113.55 | F9: 21802 | G9: normal | I9: male
A10: 15 | B10: spine_only | C10: L1 | D10: 120.63 | E10: 75.82 | F10: 32999 | G10: osteopenia | H10: 89 | I10: other
A11: 5 | B11: fused | C11: L1 | D11: 210.78 | E11: 162.35 | F11: 51857 | G11: normal | H11: 61 | I11: male
A12: 43 | B12: fused | C12: L1 | D12: 250.46 | E12: 243.87 | F12: 24776 | G12: normal | H12: 55 | I12: female
A13: 28 | B13: fused | C13: L1 | D13: 240.75 | E13: 135.58 | F13: 31169 | G13: normal | H13: 77 | I13: male
A14: 12 | B14: spine_only | C14: L1 | D14: 173.96 | E14: 120.48 | F14: 21752 | G14: normal | H14: 70 | I14: female
A15: 38 | B15: fused | C15: L1 | D15: 174.97 | E15: 176.02 | F15: 29489 | G15: normal | H15: 60 | I15: female
A16: 11 | B16: spine_only | C16: L1 | D16: 293.94 | E16: 152.24 | F16: 18843 | G16: normal | H16: 56 | I16: male
A17: 32 | B17: fused | C17: L1 | D17: 276.3 | E17: 203.13 | F17: 19032 | G17: normal | H17: 59 | I17: female
A18: 16 | B18: spine_only | C18: L1 | D18: 208.02 | E18: 166.68 | F18: 30370 | G18: normal | H18: 52 | I18: female
A19: 24 | B19: spine_only | C19: L1 | D19: 190.43 | E19: 163.25 | F19: 29705 | G19: normal | H19: 58 | I19: female
A20: 48 | B20: spine_only | C20: L1 | D20: 245.36 | E20: 146.62 | F20: 26537 | G20: normal | H20: 54 | I20: female
A21: 34 | B21: spine_only | C21: L1 | D21: 194.78 | E21: 159.17 | F21: 60619 | G21: normal | H21: 53 | I21: male
... A29: 23 | B29: spine_only | C29: L1 | D29: 312.78 | E29: 154.89 | F29: 14255 | G29: normal | H29: 52 | I29: female
A30: 50 | B30: fused | C30: L1 | D30: 190.97 | E30: 131.64 | F30: 41102 | G30: normal | I30: male
A31: 41 | B31: fused | C31: L1 | D31: 232.16 | E31: 181.63 | F31: 36694 | G31: normal | H31: 63 | I31: female
A32: 9 | B32: spine_only | C32: L1 | D32: 234.82 | E32: 169.77 | F32: 26612 | G32: normal | H32: 50 | I32: female
A33: 18 | B33: spine_only | C33: L1 | D33: 265.57 | E33: 113.84 | F33: 25549 | G33: normal | I33: female
A34: 3 | B34: fused | C34: L1 | D34: 215.1 | E34: 105.06 | F34: 35606 | G34: normal | H34: 65 | I34: male
A35: 45 | B35: fused | C35: L1 | D35: 221.15 | E35: 138.54 | F35: 27598 | G35: normal | H35: 55 | I35: female
A36: 40 | B36: fused | C36: L1 | D36: 188.11 | E36: 172.11 | F36: 28596 | G36: normal | H36: 71 | I36: male
A37: 21 | B37: spine_only | C37: L1 | D37: 150.69 | E37: 161.37 | F37: 35422 | G37: osteopenia | H37: 51 | I37: male
A38: 1 | B38: spine_only | C38: L1 | D38: 131.78 | E38: 99 | F38: 23979 | G38: osteopenia | H38: 59 | I38: female
A39: 30 | B39: spine_only | C39: L1 | D39: 251.79 | E39: 203.89 | F39: 35586 | G39: normal | H39: 70 | I39: male
A40: 29 | B40: fused | C40: L1 | D40: 225.78 | E40: 160.21 | F40: 36088 | G40: normal | H40: 79 | I40: male
A41: 17 | B41: fused | C41: L1 | D41: 153.66 | E41: 122.9 | F41: 32928 | G41: osteopenia | H41: 57 | I41: female
A42: 25 | B42: fused | C42: L1 | D42: 229.35 | E42: 118.48 | F42: 35944 | G42: normal | H42: 62 | I42: male
A43: 2 | B43: fused | C43: L1 | D43: 189.06 | E43: 115.07 | F43: 39827 | G43: normal | H43: 60 | I43: male
A44: 53 | B44: fused | C44: L1 | D44: 182.92 | E44: 103.93 | F44: 38842 | G44: normal | I44: male
A45: 10 | B45: fused | C45: L1 | D45: 156.61 | E45: 111.81 | F45: 43953 | G45: osteopenia | H45: 68 | I45: male
A46: 14 | B46: fused | C46: L1 | D46: 237.17 | E46: 142.45 | F46: 23253 | G46: normal | I46: female
A47: 8 | B47: spine_only | C47: L1 | D47: 174.72 | E47: 159.57 | F47: 30914 | G47: normal | H47: 70 | I47: male
...

Sheet manifest
A1: token | B1: position | C1: age | D1: age_band | E1: sex | F1: patient_weight | G1: patient_size | H1: convolution_kernel | I1: manufacturer | J1: manufacturer_model | K1: slice_thickness | L1: kvp | M1: config | N1: match_type | O1: prov_spine | P1: prov_pelvis | Q1: lstv_label | R1: lstv_class | S1: lstv_pelvic | T1: lstv_vertebral | U1: lstv_agreement | V1: lstv_confusion_zone | W1: has_l6 | X1: n_lumbar_labels | Y1: alignment_ok | Z1: ct_resampled_to_mask | AA1: postwrite_hip_bone_pct | AB1: partial_annotation | AC1: n_voxels_ignore | AD1: n_voxels_fg | AE1: n_voxels_bg | AF1: spine_series_uid | AG1: pelvic_series_uid | AH1: spine_bone_pct | AI1: pelvic_bone_pct | AJ1: ct_file | AK1: label_file | AL1: qc_file
A2: 9 | B2: prone | C2: 50 | D2: 50-59 | E2: female | H2: B30f | I2: SIEMENS | J2: Sensation 64 | K2: 1 | L2: 120 | M2: pelvic_native | N2: separate | P2: manual | Q2: normal | R2: 0 | S2: NORMAL | T2: NORMAL | U2: TRUE | V2: FALSE | W2: FALSE | X2: 0 | Y2: TRUE | Z2: TRUE | AA2: 74 | AB2: TRUE | AC2: 116121445 | AD2: 1843355 | AE2: 0 | AF2: 1.3.6.1.4.1.9328.50.4.9431 | AG2: 1.3.6.1.4.1.9328.50.4.8980 | AH2: 75.9 | AI2: 71.2 | AJ2: ct/0009_pelvic_ct.nii.gz | AK2: labels/0009_pelvic_label.nii.gz | AL2: qc/0009_pelvic_qc.png
A3: 16 | B3: supine | C3: 52 | D3: 50-59 | E3: female | H3: B30f | I3: SIEMENS | J3: Sensation 64 | K3: 1 | L3: 120 | M3: spine_only | N3: spine_only | O3: manual | Q3: normal | R3: 0 | T3: NORMAL | V3: FALSE | W3: FALSE | X3: 5 | Y3: TRUE | Z3: TRUE | AB3: TRUE | AC3: 129383911 | AD3: 639513 | AE3: 0 | AF3: 1.3.6.1.4.1.9328.50.4.15570 | AH3: 67.9 | AJ3: ct/0016_spine_ct.nii.gz | AK3: labels/0016_spine_label.nii.gz | AL3: qc/0016_spine_qc.png
A4: 6 | B4: supine | C4: 50 | D4: 50-59 | E4: male | H4: B30f | I4: SIEMENS | J4: Sensation 16 | K4: 1 | L4: 120 | M4: pelvic_native | N4: separate | P4: manual | Q4: SACRALIZATION | R4: 3 | S4: SACRALIZATION | T4: NORMAL | U4: FALSE | V4: TRUE | W4: FALSE | X4: 0 | Y4: TRUE | Z4: TRUE | AA4: 56.6 | AB4: TRUE | AC4: 123498384 | AD4: 2068592 | AE4: 0 | AF4: 1.3.6.1.4.1.9328.50.4.5980 | AG4: 1.3.6.1.4.1.9328.50.4.5691 | AH4: 59.5 | AI4: 56 | AJ4: ct/0006_pelvic_ct.nii.gz | AK4: labels/0006_pelvic_label.nii.gz | AL4: qc/0006_pelvic_qc.png
A5: 6 | B5: supine | C5: 50 | D5: 50-59 | E5: male | H5: B30f | I5: SIEMENS | J5: Sensation 16 | K5: 1 | L5: 120 | M5: spine_only | N5: separate | O5: manual | Q5: SACRALIZATION | R5: 3 | S5: SACRALIZATION | T5: NORMAL | U5: FALSE | V5: TRUE | W5: FALSE | X5: 5 | Y5: TRUE | Z5: TRUE | AB5: TRUE | AC5: 121700572 | AD5: 720676 | AE5: 0 | AF5: 1.3.6.1.4.1.9328.50.4.5980 | AG5: 1.3.6.1.4.1.9328.50.4.5691 | AH5: 59.5 | AI5: 56 | AJ5: ct/0006_spine_ct.nii.gz | AK5: labels/0006_spine_label.nii.gz | AL5: qc/0006_spine_qc.png
A6: 12 | B6: supine | C6: 70 | D6: 70-79 | E6: female | F6: 10.5 | H6: B | I6: Philips | J6: Brilliance 40 | K6: 1 | L6: 120 | M6: spine_only | N6: spine_only | O6: manual | Q6: normal | R6: 0 | T6: NORMAL | V6: FALSE | W6: FALSE | X6: 5 | Y6: TRUE | Z6: TRUE | AB6: TRUE | AC6: 134927115 | AD6: 601333 | AE6: 0 | AF6: 1.3.6.1.4.1.9328.50.4.11590 | AH6: 60.6 | AJ6: ct/0012_spine_ct.nii.gz | AK6: labels/0012_spine_label.nii.gz | AL6: qc/0012_spine_qc.png
A7: 7 | B7: supine | C7: 61 | D7: 60-69 | E7: male | H7: B30f | I7: SIEMENS | J7: Sensation 64 | K7: 1 | L7: 120 | M7: pelvic_native | N7: separate | P7: manual | Q7: normal | R7: 0 | S7: NORMAL | T7: NORMAL | U7: TRUE | V7: FALSE | W7: FALSE | X7: 0 | Y7: TRUE | Z7: TRUE | AA7: 55.7 | AB7: TRUE | AC7: 141207102 | AD7: 1923522 | AE7: 0 | AF7: 1.3.6.1.4.1.9328.50.4.7198 | AG7: 1.3.6.1.4.1.9328.50.4.6651 | AH7: 59.2 | AI7: 54.9 | AJ7: ct/0007_pelvic_ct.nii.gz | AK7: labels/0007_pelvic_label.nii.gz | AL7: qc/0007_pelvic_qc.png
A8: 11 | B8: supine | C8: 56 | D8: 50-59 | E8: male | F8: 10.5 | H8: B | I8: Philips | J8: Brilliance 40 | K8: 1 | L8: 140 | M8: spine_only | N8: spine_only | O8: manual | Q8: normal | R8: 0 | T8: NORMAL | V8: FALSE | W8: FALSE | X8: 5 | Y8: TRUE | Z8: TRUE | AB8: TRUE | AC8: 150321130 | AD8: 411670 | AE8: 0 | AF8: 1.3.6.1.4.1.9328.50.4.10416 | AH8: 84.7 | AJ8: ct/0011_spine_ct.nii.gz | AK8: labels/0011_spine_label.nii.gz | AL8: qc/0011_spine_qc.png
A9: 17 | B9: supine | C9: 57 | D9: 50-59 | E9: female | H9: B30f | I9: SIEMENS | J9: Sensation 64 | K9: 1 | L9: 120 | M9: fused | N9: fused | O9: manual | P9: manual | Q9: normal | R9: 0 | S9: NORMAL | T9: NORMAL | U9: TRUE | V9: FALSE | W9: FALSE | X9: 5 | Y9: TRUE | Z9: TRUE | AA9: 63.5 | AB9: FALSE | AC9: 0 | AD9: 3344297 | AE9: 126941271 | AF9: 1.3.6.1.4.1.9328.50.4.16589 | AG9: 1.3.6.1.4.1.9328.50.4.16589 | AH9: 57.2 | AI9: 58.7 | AJ9: ct/0017_ct.nii.gz | AK9: labels/0017_label.nii.gz | AL9: qc/0017_qc.png
A10: 1 | B10: prone | C10: 59 | D10: 50-59 | E10: female | H10: B30f | I10: SIEMENS | J10: Sensation 64 | K10: 1 | L10: 120 | M10: pelvic_native | N10: separate | P10: manual | Q10: normal | R10: 0 | S10: NORMAL | T10: NORMAL | U10: TRUE | V10: FALSE | W10: FALSE | X10: 0 | Y10: TRUE | Z10: TRUE | AA10: 63.3 | AB10: TRUE | AC10: 162219000 | AD10: 1621000 | AE10: 0 | AF10: 1.3.6.1.4.1.9328.50.4.2 | AG10: 1.3.6.1.4.1.9328.50.4.563 | AH10: 50 | AI10: 56.4 | AJ10: ct/0001_pelvic_ct.nii.gz | AK10: labels/0001_pelvic_label.nii.gz | AL10: qc/0001_pelvic_qc.png
A11: 1 | B11: prone | C11: 59 | D11: 50-59 | E11: female | H11: B30f | I11: SIEMENS | J11: Sensation 64 | K11: 1 | L11: 120 | M11: spine_only | N11: separate | O11: manual | Q11: normal | R11: 0 | S11: NORMAL | T11: NORMAL | U11: TRUE | V11: FALSE | W11: FALSE | X11: 5 | Y11: TRUE | Z11: TRUE | AB11: TRUE | AC11: 157808344 | AD11: 526632 | AE11: 0 | AF11: 1.3.6.1.4.1.9328.50.4.2 | AG11: 1.3.6.1.4.1.9328.50.4.563 | AH11: 50 | AI11: 56.4 | AJ11: ct/0001_spine_ct.nii.gz | AK11: labels/0001_spine_label.nii.gz | AL11: qc/0001_spine_qc.png
A12: 13 | B12: supine | C12: 52 | D12: 50-59 | E12: female | H12: B30f | I12: SIEMENS | J12: Sensation 16 | K12: 1 | L12: 120 | M12: fused | N12: fused | O12: manual | P12: manual | Q12: normal | R12: 0 | S12: NORMAL | T12: NORMAL | U12: TRUE | V12: FALSE | W12: FALSE | X12: 5 | Y12: TRUE | Z12: TRUE | AA12: 78.4 | AB12: FALSE | AC12: 0 | AD12: 2101038 | AE12: 138146002 | AF12: 1.3.6.1.4.1.9328.50.4.12365 | AG12: 1.3.6.1.4.1.9328.50.4.12365 | AH12: 84 | AI12: 76.5 | AJ12: ct/0013_ct.nii.gz | AK12: labels/0013_label.nii.gz | AL12: qc/0013_qc.png
A13: 15 | B13: prone | C13: 89 | D13: 80-89 | E13: other | H13: B30f | I13: SIEMENS | J13: Sensation 64 | K13: 1 | L13: 120 | M13: pelvic_native | N13: separate | P13: manual | Q13: SACRALIZATION | R13: 3 | S13: SACRALIZATION | T13: NORMAL | U13: FALSE | V13: TRUE | W13: FALSE | X13: 0 | Y13: TRUE | Z13: TRUE | AA13: 53.9 | AB13: TRUE | AC13: 134245059 | AD13: 2331965 | AE13: 0 | AF13: 1.3.6.1.4.1.9328.50.4.15089 | AG13: 1.3.6.1.4.1.9328.50.4.14567 | AH13: 55.6 | AI13: 52.1 | AJ13: ct/0015_pelvic_ct.nii.gz | AK13: labels/0015_pelvic_label.nii.gz | AL13: qc/0015_pelvic_qc.png
A14: 8 | B14: supine | C14: 70 | D14: 70-79 | E14: male | H14: B30f | I14: SIEMENS | J14: Sensation 64 | K14: 1 | L14: 120 | M14: pelvic_native | N14: separate | P14: manual | Q14: normal | R14: 0 | S14: NORMAL | T14: NORMAL | U14: TRUE | V14: FALSE | W14: FALSE | X14: 0 | Y14: TRUE | Z14: TRUE | AA14: 62.3 | AB14: TRUE | AC14: 169229961 | AD14: 1687927 | AE14: 0 | AF14: 1.3.6.1.4.1.9328.50.4.7889 | AG14: 1.3.6.1.4.1.9328.50.4.7701 | AH14: 56.5 | AI14: 58.3 | AJ14: ct/0008_pelvic_ct.nii.gz | AK14: labels/0008_pelvic_label.nii.gz | AL14: qc/0008_pelvic_qc.png
A15: 14 | B15: supine | E15: female | H15: B30f | I15: SIEMENS | J15: Sensation 16 | K15: 1 | L15: 120 | M15: fused | N15: fused | O15: manual | P15: manual | Q15: normal | R15: 0 | S15: NORMAL | T15: NORMAL | U15: TRUE | V15: FALSE | W15: FALSE | X15: 5 | Y15: TRUE | Z15: TRUE | AA15: 67.5 | AB15: FALSE | AC15: 0 | AD15: 2140225 | AE15: 149379007 | AF15: 1.3.6.1.4.1.9328.50.4.13405 | AG15: 1.3.6.1.4.1.9328.50.4.13405 | AH15: 76.3 | AI15: 64.7 | AJ15: ct/0014_ct.nii.gz | AK15: labels/0014_label.nii.gz | AL15: qc/0014_qc.png
A16: 3 | B16: supine | C16: 65 | D16: 60-69 | E16: male | H16: B30f | I16: SIEMENS | J16: Sensation 64 | K16: 1 | L16: 120 | M16: fused | N16: fused | O16: manual | P16: manual | Q16: normal | R16: 0 | S16: NORMAL | T16: NORMAL | U16: TRUE | V16: FALSE | W16: FALSE | X16: 5 | Y16: TRUE | Z16: TRUE | AA16: 71.5 | AB16: FALSE | AC16: 0 | AD16: 2781065 | AE16: 171020407 | AF16: 1.3.6.1.4.1.9328.50.4.2320_orientation_fixed | AG16: 1.3.6.1.4.1.9328.50.4.2320_orientation_fixed | AH16: 75.2 | AI16: 68.9 | AJ16: ct/0003_ct.nii.gz | AK16: labels/0003_label.nii.gz | AL16: qc/0003_qc.png
A17: 9 | B17: prone | C17: 50 | D17: 50-59 | E17: female | H17: B30f | I17: SIEMENS | J17: Sensation 64 | K17: 1 | L17: 120 | M17: spine_only | N17: separate | O17: manual | Q17: normal | R17: 0 | S17: NORMAL | T17: NORMAL | U17: TRUE | V17: FALSE | W17: FALSE | X17: 5 | Y17: TRUE | Z17: TRUE | AB17: TRUE | AC17: 112702775 | AD17: 543433 | AE17: 0 | AF17: 1.3.6.1.4.1.9328.50.4.9431 | AG17: 1.3.6.1.4.1.9328.50.4.8980 | AH17: 75.9 | AI17: 71.2 | AJ17: ct/0009_spine_ct.nii.gz | AK17: labels/0009_spine_label.nii.gz | AL17: qc/0009_spine_qc.png
A18: 5 | B18: prone | C18: 61 | D18: 60-69 | E18: male | H18: B30f | I18: SIEMENS | J18: Sensation 16 | K18: 1 | L18: 120 | M18: fused | N18: fused | O18: manual | P18: manual | Q18: normal | R18: 0 | S18: NORMAL | T18: NORMAL | U18: TRUE | V18: FALSE | W18: FALSE | X18: 5 | Y18: TRUE | Z18: TRUE | AA18: 54.6 | AB18: FALSE | AC18: 0 | AD18: 3585776 | AE18: 101533968 | AF18: 1.3.6.1.4.1.9328.50.4.4716 | AG18: 1.3.6.1.4.1.9328.50.4.4716 | AH18: 64.6 | AI18: 56.2 | AJ18: ct/0005_ct.nii.gz | AK18: labels/0005_label.nii.gz | AL18: qc/0005_qc.png
A19: 18 | B19: supine | E19: female | H19: B30f | I19: SIEMENS | J19: Sensation 64 | K19: 1 | L19: 120 | M19: pelvic_native | N19: separate | P19: manual | Q19: normal | R19: 0 | S19: NORMAL | T19: NORMAL | U19: TRUE | V19: FALSE | W19: FALSE | X19: 0 | Y19: TRUE | Z19: TRUE | AA19: 70.3 | AB19: TRUE | AC19: 129240299 | AD19: 2093845 | AE19: 0 | AF19: 1.3.6.1.4.1.9328.50.4.17584 | AG19: 1.3.6.1.4.1.9328.50.4.18086 | AH19: 84 | AI19: 70.2 | AJ19: ct/0018_pelvic_ct.nii.gz | AK19: labels/0018_pelvic_label.nii.gz | AL19: qc/0018_pelvic_qc.png
A20: 18 | B20: supine | E20: female | H20: B30f | I20: SIEMENS | J20: Sensation 64 | K20: 1 | L20: 120 | M20: spine_only | N20: separate | O20: manual | Q20: normal | R20: 0 | S20: NORMAL | T20: NORMAL | U20: TRUE | V20: FALSE | W20: FALSE | X20: 5 | Y20: TRUE | Z20: TRUE | AB20: TRUE | AC20: 130596117 | AD20: 738027 | AE20: 0 | AF20: 1.3.6.1.4.1.9328.50.4.17584 | AG20: 1.3.6.1.4.1.9328.50.4.18086 | AH20: 84 | AI20: 70.2 | AJ20: ct/0018_spine_ct.nii.gz | AK20: labels/0018_spine_label.nii.gz | AL20: qc/0018_spine_qc.png
A21: 19 | B21: decubitus_right | C21: 51 | D21: 50-59 | E21: female | H21: FC13 | I21: TOSHIBA | J21: Aquilion | K21: 1 | L21: 120 | M21: pelvic_native | N21: separate | P21: manual | Q21: normal | R21: 0 | S21: NORMAL | T21: NORMAL | U21: TRUE | V21: FALSE | W21: FALSE | X21: 0 | Y21: TRUE | Z21: TRUE | AA21: 89.3 | AB21: TRUE | AC21: 124796663 | AD21: 1556745 | AE21: 0 | AF21: 1.3.6.1.4.1.9328.50.4.19520 | AG21: 1.3.6.1.4.1.9328.50.4.18592 | AH21: 88.6 | AI21: 84.6 | AJ21: ct/0019_pelvic_ct.nii.gz | AK21: labels/0019_pelvic_label.nii.gz | AL21: qc/0019_pelvic_qc.png
A22: 15 | B22: prone | C22: 89 | D22: 80-89 | E22: other | H22: B30f | I22: SIEMENS | J22: Sensation 64 | K22: 1 | L22: 120 | M22: spine_only | N22: separate | O22: manual | Q22: SACRALIZATION | R22: 3 | S22: SACRALIZATION | T22: NORMAL | U22: FALSE | V22: TRUE | W22: FALSE | X22: 5 | Y22: TRUE | Z22: TRUE | AB22: TRUE | AC22: 124054432 | AD22: 726112 | AE22: 0 | AF22: 1.3.6.1.4.1.9328.50.4.15089 | AG22: 1.3.6.1.4.1.9328.50.4.14567 | AH22: 55.6 | AI22: 52.1 | AJ22: ct/0015_spine_ct.nii.gz | AK22: labels/0015_spine_label.nii.gz | AL22: qc/0015_spine_qc.png
A23: 4 | B23: supine | C23: 51 | D23: 50-59 | E23: male | H23: B30f | I23: SIEMENS | J23: Sensation 64 | K23: 1 | L23: 120 | M23: pelvic_native | N23: separate | P23: manual | Q23: SACRALIZATION | R23: 3 | S23: SACRALIZATION | T23: LUMBARIZATION | U23: FALSE | V23: TRUE | W23: FALSE | X23: 0 | Y23: TRUE | Z23: TRUE | AA23: 53.8 | AB23: TRUE | AC23: 140803088 | AD23: 1803248 | AE23: 0 | AF23: 1.3.6.1.4.1.9328.50.4.4371 | AG23: 1.3.6.1.4.1.9328.50.4.3828 | AH23: 52.1 | AI23: 51.7 | AJ23: ct/0004_pelvic_ct.nii.gz | AK23: labels/0004_pelvic_label.nii.gz | AL23: qc/0004_pelvic_qc.png
A24: 19 | B24: decubitus_right | C24: 51 | D24: 50-59 | E24: female | H24: FC13 | I24: TOSHIBA | J24: Aquilion | K24: 1 | L24: 120 | M24: spine_only | N24: separate | O24: manual | Q24: normal | R24: 0 | S24: NORMAL | T24: NORMAL | U24: TRUE | V24: FALSE | W24: FALSE | X24: 5 | Y24: TRUE | Z24: TRUE | AB24: TRUE | AC24: 115537512 | AD24: 854424 | AE24: 0 | AF24: 1.3.6.1.4.1.9328.50.4.19520 | AG24: 1.3.6.1.4.1.9328.50.4.18592 | AH24: 88.6 | AI24: 84.6 | AJ24: ct/0019_spine_ct.nii.gz | AK24: labels/0019_spine_label.nii.gz | AL24: qc/0019_spine_qc.png
A25: 7 | B25: supine | C25: 61 | D25: 60-69 | E25: male | H25: B30f | I25: SIEMENS | J25: Sensation 64 | K25: 1 | L25: 120 | M25: spine_only | N25: separate | O25: manual | Q25: normal | R25: 0 | S25: NORMAL | T25: NORMAL | U25: TRUE | V25: FALSE | W25: FALSE | X25: 5 | Y25: TRUE | Z25: TRUE | AB25: TRUE | AC25: 130657681 | AD25: 676463 | AE25: 0 | AF25: 1.3.6.1.4.1.9328.50.4.7198 | AG25: 1.3.6.1.4.1.9328.50.4.6651 | AH25: 59.2 | AI25: 54.9 | AJ25: ct/0007_spine_ct.nii.gz | AK25: labels/0007_spine_label.nii.gz | AL25: qc/0007_spine_qc.png
A26: 20 | B26: supine | C26: 54 | D26: 50-59 | E26: male | H26: FC13 | I26: TOSHIBA | J26: Aquilion | K26: 1 | L26: 120 | M26: pelvic_native | N26: separate | P26: manual | Q26: normal | R26: 0 | S26: NORMAL | T26: NORMAL | U26: TRUE | V26: FALSE | W26: FALSE | X26: 0 | Y26: TRUE | Z26: TRUE | AA26: 75.5 | AB26: TRUE | AC26: 151544676 | AD26: 2595996 | AE26: 0 | AF26: 1.3.6.1.4.1.9328.50.4.19969 | AG26: 1.3.6.1.4.1.9328.50.4.20549 | AH26: 73.7 | AI26: 72.3 | AJ26: ct/0020_pelvic_ct.nii.gz | AK26: labels/0020_pelvic_label.nii.gz | AL26: qc/0020_pelvic_qc.png
A27: 20 | B27: supine | C27: 54 | D27: 50-59 | E27: male | H27: FC13 | I27: TOSHIBA | J27: Aquilion | K27: 1 | L27: 120 | M27: spine_only | N27: separate | O27: manual | Q27: normal | R27: 0 | S27: NORMAL | T27: NORMAL | U27: TRUE | V27: FALSE | W27: FALSE | X27: 5 | Y27: TRUE | Z27: TRUE | AB27: TRUE | AC27: 150051970 | AD27: 942974 | AE27: 0 | AF27: 1.3.6.1.4.1.9328.50.4.19969 | AG27: 1.3.6.1.4.1.9328.50.4.20549 | AH27: 73.7 | AI27: 72.3 | AJ27: ct/0020_spine_ct.nii.gz | AK27: labels/0020_spine_label.nii.gz | AL27: qc/0020_spine_qc.png
A28: 24 | B28: supine | C28: 58 | D28: 50-59 | E28: female | H28: STANDARD | I28: GE MEDICAL SYSTEMS | J28: LightSpeed16 | K28: 1.25 | L28: 120 | M28: spine_only | N28: separate | O28: manual | Q28: normal | R28: 0 | S28: NORMAL | T28: NORMAL | U28: TRUE | V28: FALSE | W28: FALSE | X28: 5 | Y28: TRUE | Z28: TRUE | AB28: TRUE | AC28: 133908332 | AD28: 571540 | AE28: 0 | AF28: 1.3.6.1.4.1.9328.50.4.24902 | AG28: 1.3.6.1.4.1.9328.50.4.24418 | AH28: 65.5 | AI28: 65.8 | AJ28: ct/0024_spine_ct.nii.gz | AK28: labels/0024_spine_label.nii.gz | AL28: qc/0024_spine_qc.png
A29: 21 | B29: supine | C29: 51 | D29: 50-59 | E29: male | H29: STANDARD | I29: GE MEDICAL SYSTEMS | J29: LightSpeed16 | K29: 1.25 | L29: 120 | M29: pelvic_native | N29: separate | P29: manual | Q29: normal | R29: 0 | S29: NORMAL | T29: NORMAL | U29: TRUE | V29: FALSE | W29: FALSE | X29: 0 | Y29: TRUE | Z29: TRUE | AA29: 60.9 | AB29: TRUE | AC29: 159865893 | AD29: 1876955 | AE29: 0 | AF29: 1.3.6.1.4.1.9328.50.4.26707 | AG29: 1.3.6.1.4.1.9328.50.4.21481 | AH29: 56.7 | AI29: 56.1 | AJ29: ct/0021_pelvic_ct.nii.gz | AK29: labels/0021_pelvic_label.nii.gz | AL29: qc/0021_pelvic_qc.png
A30: 4 | B30: supine | C30: 51 | D30: 50-59 | E30: male | H30: B30f | I30: SIEMENS | J30: Sensation 64 | K30: 1 | L30: 120 | M30: spine_only | N30: separate | O30: manual | Q30: SACRALIZATION | R30: 3 | S30: SACRALIZATION | T30: LUMBARIZATION | U30: FALSE | V30: TRUE | W30: TRUE | X30: 6 | Y30: TRUE | Z30: TRUE | AB30: TRUE | AC30: 135592031 | AD30: 722849 | AE30: 0 | AF30: 1.3.6.1.4.1.9328.50.4.4371 | AG30: 1.3.6.1.4.1.9328.50.4.3828 | AH30: 52.1 | AI30: 51.7 | AJ30: ct/0004_spine_ct.nii.gz | AK30: labels/0004_spine_label.nii.gz | AL30: qc/0004_spine_qc.png
A31: 22 | B31: supine | C31: 50 | D31: 50-59 | E31: female | H31: STANDARD | I31: GE MEDICAL SYSTEMS | J31: LightSpeed16 | K31: 1.25 | L31: 120 | M31: pelvic_native | N31: pelvic_only | P31: manual | Q31: SEMI_SACRALIZATION | R31: 0 | S31: SEMI_SACRALIZATION | V31: FALSE | W31: FALSE | X31: 0 | Y31: TRUE | Z31: TRUE | AA31: 74.8 | AB31: TRUE | AC31: 145178047 | AD31: 1622593 | AE31: 0 | AG31: 1.3.6.1.4.1.9328.50.4.22612 | AI31: 72.6 | AJ31: ct/0022_pelvic_ct.nii.gz | AK31: labels/0022_pelvic_label.nii.gz | AL31: qc/0022_pelvic_qc.png
A32: 23 | B32: supine | C32: 52 | D32: 50-59 | E32: female | H32: STANDARD | I32: GE MEDICAL SYSTEMS | J32: LightSpeed16 | K32: 1.25 | L32: 120 | M32: pelvic_native | N32: separate | P32: manual | Q32: normal | R32: 0 | S32: NORMAL | T32: NORMAL | U32: TRUE | V32: FALSE | W32: FALSE | X32: 0 | Y32: TRUE | Z32: TRUE | AA32: 79.4 | AB32: TRUE | AC32: 155801875 | AD32: 1222381 | AE32: 0 | AF32: 1.3.6.1.4.1.9328.50.4.23833 | AG32: 1.3.6.1.4.1.9328.50.4.23196 | AH32: 86.7 | AI32: 76.8 | AJ32: ct/0023_pelvic_ct.nii.gz | AK32: labels/0023_pelvic_label.nii.gz | AL32: qc/0023_pelvic_qc.png
A33: 23 | B33: supine | C33: 52 | D33: 50-59 | E33: female | H33: STANDARD | I33: GE MEDICAL SYSTEMS | J33: LightSpeed16 | K33: 1.25 | L33: 120 | M33: spine_only | N33: separate | O33: manual | Q33: normal | R33: 0 | S33: NORMAL | T33: NORMAL | U33: TRUE | V33: FALSE | W33: FALSE | X33: 5 | Y33: TRUE | Z33: TRUE | AB33: TRUE | AC33: 150843955 | AD33: 413133 | AE33: 0 | AF33: 1.3.6.1.4.1.9328.50.4.23833 | AG33: 1.3.6.1.4.1.9328.50.4.23196 | AH33: 86.7 | AI33: 76.8 | AJ33: ct/0023_spine_ct.nii.gz | AK33: labels/0023_spine_label.nii.gz | AL33: qc/0023_spine_qc.png
A34: 24 | B34: supine | C34: 58 | D34: 50-59 | E34: female | H34: STANDARD | I34: GE MEDICAL SYSTEMS | J34: LightSpeed16 | K34: 1.25 | L34: 120 | M34: pelvic_native | N34: separate | P34: manual | Q34: normal | R34: 0 | S34: NORMAL | T34: NORMAL | U34: TRUE | V34: FALSE | W34: FALSE | X34: 0 | Y34: TRUE | Z34: TRUE | AA34: 70.2 | AB34: TRUE | AC34: 141988941 | AD34: 1665971 | AE34: 0 | AF34: 1.3.6.1.4.1.9328.50.4.24902 | AG34: 1.3.6.1.4.1.9328.50.4.24418 | AH34: 65.5 | AI34: 65.8 | AJ34: ct/0024_pelvic_ct.nii.gz | AK34: labels/0024_pelvic_label.nii.gz | AL34: qc/0024_pelvic_qc.png
A35: 10 | B35: supine | C35: 68 | D35: 60-69 | E35: male | H35: STANDARD | I35: GE MEDICAL SYSTEMS | J35: LightSpeed16 | K35: 1.25 | L35: 120 | M35: fused | N35: fused | O35: manual | P35: manual | Q35: normal | R35: 0 | S35: NORMAL | T35: NORMAL | U35: TRUE | V35: FALSE | W35: FALSE | X35: 5 | Y35: TRUE | Z35: TRUE | AA35: 57.9 | AB35: FALSE | AC35: 0 | AD35: 3863991 | AE35: 138480201 | AF35: 1.3.6.1.4.1.9328.50.4.9865 | AG35: 1.3.6.1.4.1.9328.50.4.9865 | AH35: 63 | AI35: 57.2 | AJ35: ct/0010_ct.nii.gz | AK35: labels/0010_label.nii.gz | AL35: qc/0010_qc.png
A36: 26 | B36: prone | C36: 51 | D36: 50-59 | E36: male | H36: STANDARD | I36: GE MEDICAL SYSTEMS | J36: LightSpeed16 | K36: 1.25 | L36: 120 | M36: spine_only | N36: separate | O36: manual | Q36: normal | R36: 0 | S36: NORMAL | T36: NORMAL | U36: TRUE | V36: FALSE | W36: FALSE | X36: 5 | Y36: TRUE | Z36: TRUE | AB36: TRUE | AC36: 147420177 | AD36: 691183 | AE36: 0 | AF36: 1.3.6.1.4.1.9328.50.4.27293 | AG36: 1.3.6.1.4.1.9328.50.4.27863 | AH36: 59.3 | AI36: 53.6 | AJ36: ct/0026_spine_ct.nii.gz | AK36: labels/0026_spine_label.nii.gz | AL36: qc/0026_spine_qc.png
A37: 8 | B37: supine | C37: 70 | D37: 70-79 | E37: male | H37: B30f | I37: SIEMENS | J37: Sensation 64 | K37: 1 | L37: 120 | M37: spine_only | N37: separate | O37: manual | Q37: normal | R37: 0 | S37: NORMAL | T37: NORMAL | U37: TRUE | V37: FALSE | W37: FALSE | X37: 5 | Y37: TRUE | Z37: TRUE | AB37: TRUE | AC37: 159327936 | AD37: 579904 | AE37: 0 | AF37: 1.3.6.1.4.1.9328.50.4.7889 | AG37: 1.3.6.1.4.1.9328.50.4.7701 | AH37: 56.5 | AI37: 58.3 | AJ37: ct/0008_spine_ct.nii.gz | AK37: labels/0008_spine_label.nii.gz | AL37: qc/0008_spine_qc.png
A38: 25 | B38: supine | C38: 62 | D38: 60-69 | E38: male | H38: STANDARD | I38: GE MEDICAL SYSTEMS | J38: LightSpeed16 | K38: 1.25 | L38: 120 | M38: fused | N38: fused | O38: manual | P38: manual | Q38: normal | R38: 0 | S38: NORMAL | T38: NORMAL | U38: TRUE | V38: FALSE | W38: FALSE | X38: 5 | Y38: TRUE | Z38: TRUE | AA38: 71 | AB38: FALSE | AC38: 0 | AD38: 2792305 | AE38: 155542671 | AF38: 1.3.6.1.4.1.9328.50.4.26036 | AG38: 1.3.6.1.4.1.9328.50.4.26036 | AH38: 77.2 | AI38: 70.1 | AJ38: ct/0025_ct.nii.gz | AK38: labels/0025_label.nii.gz | AL38: qc/0025_qc.png
A39: 21 | B39: supine | C39: 51 | D39: 50-59 | E39: male | H39: STANDARD | I39: GE MEDICAL SYSTEMS | J39: LightSpeed16 | K39: 1.25 | L39: 120 | M39: spine_only | N39: separate | O39: manual | Q39: normal | R39: 0 | S39: NORMAL | T39: NORMAL | U39: TRUE | V39: FALSE | W39: FALSE | X39: 5 | Y39: TRUE | Z39: TRUE | AB39: TRUE | AC39: 151346565 | AD39: 696955 | AE39: 0 | AF39: 1.3.6.1.4.1.9328.50.4.26707 | AG39: 1.3.6.1.4.1.9328.50.4.21481 | AH39: 56.7 | AI39: 56.1 | AJ39: ct/0021_spine_ct.nii.gz | AK39: labels/0021_spine_label.nii.gz | AL39: qc/0021_spine_qc.png
A40: 2 | B40: prone | C40: 60 | D40: 60-69 | E40: male | H40: B30f | I40: SIEMENS | J40: Sensation 64 | K40: 1 | L40: 120 | M40: fused | N40: fused | O40: manual | P40: manual | Q40: normal | R40: 0 | S40: NORMAL | T40: NORMAL | U40: TRUE | V40: FALSE | W40: FALSE | X40: 5 | Y40: TRUE | Z40: TRUE | AA40: 62.2 | AB40: FALSE | AC40: 0 | AD40: 3136130 | AE40: 163849598 | AF40: 1.3.6.1.4.1.9328.50.4.1241 | AG40: 1.3.6.1.4.1.9328.50.4.1241 | AH40: 64.5 | AI40: 60.7 | AJ40: ct/0002_ct.nii.gz | AK40: labels/0002_label.nii.gz | AL40: qc/0002_qc.png
...
